<?xml version="1.0"?>                                   <!-- XML声明：指定XML版本 -->
<robot name="example">                                  <!-- 定义机器人模型，name属性指定机器人名称 -->

    <!-- 定义材质 blue -->
    <material name="blue">                              
        <color rgba="0 0 1 1" />                        <!-- color 元素定义材质的颜色，rgba 属性依次为 红、绿、蓝、透明度 (范围 0–1)，此处表示纯蓝且不透明 -->
    </material>                               

    <!-- 定义材质 red -->
    <material name="red">
        <color rgba="1 0 0 1" />
    </material>

    <!-- 定义材质 black -->
    <material name="black">
        <color rgba="0 0 0 1" />
    </material>
  
    <!-- 定义材质 white -->
    <material name="white">
        <color rgba="1 1 1 1" />
    </material>

    <!-- 定义第1个杆 link -->
    <link name="base_link">                             
        <visual>                                        <!-- visual 元素：描述链接外观 -->
            <origin xyz="0 0 0.0265"  rpy="0 0 0"/>        <!-- 定义 link 在坐标系中的位置 xyz 与姿态 roll pitch yaw -->
            <geometry>                                  <!-- geometry 元素：包含几何形状定义 -->
                <box size="0.11 0.112 0.044"/>          <!-- box 定义一个长方体，size 属性依次为 x、y、z 方向的尺寸（单位：米） -->
            </geometry>                       
            <material name="blue"/>                     <!-- 应用先前定义的 blue 材质 -->
        </visual>                              
    </link>                                   

    <!-- 定义第2个 link 轮子1-->
    <link name="wheel_1">                           
        <visual>                                        <!-- visual 元素：描述链接外观 -->
            <origin xyz="0 0 0" rpy="1.57 0 0"/>        <!-- 定义 visual 在链接坐标系中的位置与姿态 -->
            <geometry>                                  <!-- geometry 元素：包含几何形状定义 -->
                <cylinder length="0.015" radius="0.022"/> 
            </geometry>                        
            <material name="black"/>                      <!-- 应用先前定义的 blue 材质 -->
        </visual>                             
    </link> 

    <!-- 定义第3个 link 轮子2-->
    <link name="wheel_2">                           
        <visual>                                        <!-- visual 元素：描述链接外观 -->
            <origin xyz="0 0 0" rpy="1.57 0 0"/>        <!-- 定义 visual 在链接坐标系中的位置与姿态 -->
            <geometry>                                  <!-- geometry 元素：包含几何形状定义 -->
                <cylinder length="0.015" radius="0.022"/> 
            </geometry>                        
            <material name="black"/>                      <!-- 应用先前定义的 blue 材质 -->
        </visual>                             
    </link> 


    <!-- 定义第4个 link 万向轮-->
    <link name="caster_wheel">                           
        <visual>                                        <!-- visual 元素：描述链接外观 -->
            <origin xyz="0 0 0" rpy="1.57 0 0"/>        <!-- 定义 visual 在链接坐标系中的位置与姿态 -->
            <geometry>                                  <!-- geometry 元素：包含几何形状定义 -->
                <sphere radius="0.009"/>
            </geometry>                        
            <material name="white"/>                      <!-- 应用先前定义的 blue 材质 -->
        </visual>                             
    </link> 

    <joint name="wheel_1_joint" type="continuous">          
        <parent link="base_link"/>
        <child link="wheel_1"/>
        <origin xyz="0.025 0.05 0.022" rpy="0 0 0"/>          
        <axis xyz="0 1 0"/>
        
    </joint>


    <joint name="wheel_2_joint" type="continuous">          
        <parent link="base_link"/>
        <child link="wheel_2"/>
        <origin xyz="0.025 -0.05 0.022" rpy="0 0 0"/>       
        <axis xyz="0 1 0"/>
    </joint>

    
    <joint name="caster_wheel_joint" type="continuous">           
        <parent link="base_link"/>
        <child link="caster_wheel"/>
        <origin xyz="-0.035 0.0 0.009" rpy="0 0 0"/>         
        <axis xyz="0 1 0"/>
    </joint>

</robot>